Workbook
Name 信号: [1]GRAPH!$I$129:$X$129
Name 機番: [1]GRAPH!$BP$130:$BP$230
Name 稼働: [1]Magnet!$T$24:$T$25
Name 除外除く信号: [1]GRAPH!$AG$130:$AV$130

Sheet OEE AHV
B1: การคำนวณ OEE | Z1: *I. จำนวนชิ้นงานเสีย (Defect Count) | AE1: *D. เวลาหยุดตามแผน (Planned Downtime) | AL1: *E. เวลาหยุดนอกแผน (Unplanned Downtime)
B2: Date | C2: Model | D2: Machine No. | E2: Cycle time | F2: Working HOURS. | G2: A. เวลาทั้งหมด (Total Time) minute | H2: B. เวลาที่ไม่ได้ วางแผนผลิต (Schedule Loss) *Break time | I2: C. เวลาที่ควร ทำงาน (Planned Production Time) A - B | J2: D. เวลาหยุด ตามแผน (Planned Downtime) | K2: E. เวลาหยุด นอกแผน (Unplanned Downtime) | L2: F. รวมเวลาหยุด ทั้งหมด (Total Stop Time) D + E | M2: G. เวลาที่ เครื่องจักร ทำงานจริง (Operating Time / Run Time) C - F | N2: M | O2: Column1 | P2: N | Q2: H. จำนวนชิ้น งานทั้งหมด ที่ผลิตได้ (Total Count) | R2: I. จำนวนชิ้น งานเสีย (Defect Count) | S2: J. จำนวนชิ้น งานดี (Good Count) H - I | T2: K. จำนวนชิ้นงาน ที่ควรผลิต ได้ตาม มาตรฐาน G / cycletime | U2: Availability (A%) (G / C) | V2: Performance (P%) (H / K) | W2: Quality (Q%) (J / H) | X2: OEE A% * P% * Q% | AE2: จำนวนครั้ง ที่หยุดเครื่อง Clean Machine | AF2: Intray & Out Tray | AG2: Set Lot | AH2: Wait 4 Tray สุดท้ายของ Lot. | AI2: QC Check master | AJ2: Prod.Check master แบบไม่ดูหน้าจอ Monitor | AK2: Prod.Check master แบบดูหน้าจอ Monitor | AL2: Adj. machine | AM2: PT-Chuck alarm | AN2: PT-Chuck miss alarm | AO2: PT-Full tray drop | AP2: PT-Lifter alarm | AQ2: PT-Supportter alarm | AR2: PT-Z Over load | AS2: Supply work float NG | AT2: Visual 3 chuck alarm | AU2: Visual 5 under pusher alarm | AV2: Wait part
B3: 46055 | C3: DRD | D3: AHV-01 | E3: 4.3 | F3: 24 | G3: =F3*60 -> 1440 | H3: 0 | I3: =+G3-H3 -> 1440 | J3: =SUM(AF3:AK3) -> 92.611979 | K3: =SUM(AL3:AX3) -> 219 | L3: =+K3+J3 -> 311.61198 | M3: =+I3-L3 -> 1128.388 | N3: 7160 | P3: 7676 | Q3: =SUM(N3:P3) -> 14836 | R3: =SUM(Z3:AD3) -> 1 | S3: =+Q3-R3 -> 14835 | T3: =IFERROR((M3*60)/E3,"-") -> 15744.949 | U3: =IFERROR(M3/I3," ") -> 0.78360279 | V3: =IFERROR(Q3/T3," ") -> 0.94227043 | W3: =IFERROR(S3/Q3," ") -> 0.9999326 | X3: =IFERROR(U3*V3*W3," ") -> 0.73831597 | Z3: 1 | AE3: =Table24[[#This Row],[H. จำนวนชิ้น งานทั้งหมด ที่ผลิตได้ (Total Count)]]/512*1 -> 28.976562 | AF3: =(Q3/512*68/60) -> 32.840104 | AG3: =(Q3/512*35/60) -> 16.902995 | AH3: =(Q3/512*37/60) -> 17.86888 | AI3: 10 | AJ3: 5 | AK3: 10 | AL3: =SUMIFS(Table1[Column1],Table1[Date],'OEE AHV'!$B3,Table1[M/C],'OEE AHV'!$D3,Table1[Case downtime],'OEE AHV'!AL$2) -> 0 | AM3: =SUMIFS(Table1[Column1],Table1[Date],'OEE AHV'!$B3,Table1[M/C],'OEE AHV'!$D3,Table1[Case downtime],'OEE AHV'!AM$2) -> 0 | AN3: =SUMIFS(Table1[Column1],Table1[Date],'OEE AHV'!$B3,Table1[M/C],'OEE AHV'!$D3,Table1[Case downtime],'OEE AHV'!AN$2) -> 0 | AO3: =SUMIFS(Table1[Column1],Table1[Date],'OEE AHV'!$B3,Table1[M/C],'OEE AHV'!$D3,Table1[Case downtime],'OEE AHV'!AO$2) -> 0 | AP3: =SUMIFS(Table1[Column1],Table1[Date],'OEE AHV'!$B3,Table1[M/C],'OEE AHV'!$D3,Table1[Case downtime],'OEE AHV'!AP$2) -> 0 | AQ3: =SUMIFS(Table1[Column1],Table1[Date],'OEE AHV'!$B3,Table1[M/C],'OEE AHV'!$D3,Table1[Case downtime],'OEE AHV'!AQ$2) -> 0 | AR3: =SUMIFS(Table1[Column1],Table1[Date],'OEE AHV'!$B3,Table1[M/C],'OEE AHV'!$D3,Table1[Case downtime],'OEE AHV'!AR$2) -> 0 | AS3: =SUMIFS(Table1[Column1],Table1[Date],'OEE AHV'!$B3,Table1[M/C],'OEE AHV'!$D3,Table1[Case downtime],'OEE AHV'!AS$2) -> 0 | ... AX3: =SUMIFS(Table1[Column1],Table1[Date],'OEE AHV'!$B3,Table1[M/C],'OEE AHV'!$D3,Table1[Case downtime],'OEE AHV'!AX$2) -> 0
B4: 46056 | C4: DRD | D4: AHV-01 | E4: 4.3 | F4: 24 | G4: =F4*60 -> 1440 | H4: 0 | I4: =+G4-H4 -> 1440 | J4: =SUM(AF4:AK4) -> 101.94531 | K4: =SUM(AL4:AX4) -> 140 | L4: =+K4+J4 -> 241.94531 | M4: =+I4-L4 -> 1198.0547 | N4: 7672 | P4: 9212 | Q4: =SUM(N4:P4) -> 16884 | R4: =SUM(Z4:AD4) -> 0 | S4: =+Q4-R4 -> 16884 | T4: =IFERROR((M4*60)/E4,"-") -> 16717.042 | U4: =IFERROR(M4/I4," ") -> 0.83198242 | V4: =IFERROR(Q4/T4," ") -> 1.0099873 | W4: =IFERROR(S4/Q4," ") -> 1 | X4: =IFERROR(U4*V4*W4," ") -> 0.84029167 | Z4: 0 | AE4: =Table24[[#This Row],[H. จำนวนชิ้น งานทั้งหมด ที่ผลิตได้ (Total Count)]]/512*1 -> 32.976562 | AF4: =(Q4/512*68/60) -> 37.373438 | AG4: =(Q4/512*35/60) -> 19.236328 | AH4: =(Q4/512*37/60) -> 20.335547 | AI4: 10 | AJ4: 5 | AK4: 10 | AL4: =SUMIFS(Table1[Column1],Table1[Date],'OEE AHV'!$B4,Table1[M/C],'OEE AHV'!$D4,Table1[Case downtime],'OEE AHV'!AL$2) -> 0 | AM4: =SUMIFS(Table1[Column1],Table1[Date],'OEE AHV'!$B4,Table1[M/C],'OEE AHV'!$D4,Table1[Case downtime],'OEE AHV'!AM$2) -> 0 | AN4: =SUMIFS(Table1[Column1],Table1[Date],'OEE AHV'!$B4,Table1[M/C],'OEE AHV'!$D4,Table1[Case downtime],'OEE AHV'!AN$2) -> 0 | AO4: =SUMIFS(Table1[Column1],Table1[Date],'OEE AHV'!$B4,Table1[M/C],'OEE AHV'!$D4,Table1[Case downtime],'OEE AHV'!AO$2) -> 0 | AP4: =SUMIFS(Table1[Column1],Table1[Date],'OEE AHV'!$B4,Table1[M/C],'OEE AHV'!$D4,Table1[Case downtime],'OEE AHV'!AP$2) -> 0 | AQ4: =SUMIFS(Table1[Column1],Table1[Date],'OEE AHV'!$B4,Table1[M/C],'OEE AHV'!$D4,Table1[Case downtime],'OEE AHV'!AQ$2) -> 0 | AR4: =SUMIFS(Table1[Column1],Table1[Date],'OEE AHV'!$B4,Table1[M/C],'OEE AHV'!$D4,Table1[Case downtime],'OEE AHV'!AR$2) -> 0 | AS4: =SUMIFS(Table1[Column1],Table1[Date],'OEE AHV'!$B4,Table1[M/C],'OEE AHV'!$D4,Table1[Case downtime],'OEE AHV'!AS$2) -> 0 | ... AX4: =SUMIFS(Table1[Column1],Table1[Date],'OEE AHV'!$B4,Table1[M/C],'OEE AHV'!$D4,Table1[Case downtime],'OEE AHV'!AX$2) -> 0
B5: 46057 | C5: DRD | D5: AHV-01 | E5: 4.3 | F5: 24 | G5: =F5*60 -> 1440 | H5: 0 | I5: =+G5-H5 -> 1440 | J5: =SUM(AF5:AK5) -> 99.630208 | K5: =SUM(AL5:AX5) -> 254 | L5: =+K5+J5 -> 353.63021 | M5: =+I5-L5 -> 1086.3698 | N5: 8188 | P5: 8188 | Q5: =SUM(N5:P5) -> 16376 | R5: =SUM(Z5:AD5) -> 0 | S5: =+Q5-R5 -> 16376 | T5: =IFERROR((M5*60)/E5,"-") -> 15158.648 | U5: =IFERROR(M5/I5," ") -> 0.75442347 | V5: =IFERROR(Q5/T5," ") -> 1.0803074 | W5: =IFERROR(S5/Q5," ") -> 1 | X5: =IFERROR(U5*V5*W5," ") -> 0.81500926 | Z5: 0 | AE5: =Table24[[#This Row],[H. จำนวนชิ้น งานทั้งหมด ที่ผลิตได้ (Total Count)]]/512*1 -> 31.984375 | AF5: =(Q5/512*68/60) -> 36.248958 | AG5: =(Q5/512*35/60) -> 18.657552 | AH5: =(Q5/512*37/60) -> 19.723698 | AI5: 10 | AJ5: 5 | AK5: 10 | AL5: =SUMIFS(Table1[Column1],Table1[Date],'OEE AHV'!$B5,Table1[M/C],'OEE AHV'!$D5,Table1[Case downtime],'OEE AHV'!AL$2) -> 15 | AM5: =SUMIFS(Table1[Column1],Table1[Date],'OEE AHV'!$B5,Table1[M/C],'OEE AHV'!$D5,Table1[Case downtime],'OEE AHV'!AM$2) -> 0 | AN5: =SUMIFS(Table1[Column1],Table1[Date],'OEE AHV'!$B5,Table1[M/C],'OEE AHV'!$D5,Table1[Case downtime],'OEE AHV'!AN$2) -> 0 | AO5: =SUMIFS(Table1[Column1],Table1[Date],'OEE AHV'!$B5,Table1[M/C],'OEE AHV'!$D5,Table1[Case downtime],'OEE AHV'!AO$2) -> 0 | AP5: =SUMIFS(Table1[Column1],Table1[Date],'OEE AHV'!$B5,Table1[M/C],'OEE AHV'!$D5,Table1[Case downtime],'OEE AHV'!AP$2) -> 0 | AQ5: =SUMIFS(Table1[Column1],Table1[Date],'OEE AHV'!$B5,Table1[M/C],'OEE AHV'!$D5,Table1[Case downtime],'OEE AHV'!AQ$2) -> 0 | AR5: =SUMIFS(Table1[Column1],Table1[Date],'OEE AHV'!$B5,Table1[M/C],'OEE AHV'!$D5,Table1[Case downtime],'OEE AHV'!AR$2) -> 0 | AS5: =SUMIFS(Table1[Column1],Table1[Date],'OEE AHV'!$B5,Table1[M/C],'OEE AHV'!$D5,Table1[Case downtime],'OEE AHV'!AS$2) -> 0 | ... AX5: =SUMIFS(Table1[Column1],Table1[Date],'OEE AHV'!$B5,Table1[M/C],'OEE AHV'!$D5,Table1[Case downtime],'OEE AHV'!AX$2) -> 0
B6: 46058 | C6: DRD | D6: AHV-01 | E6: 4.3 | F6: 24 | G6: =F6*60 -> 1440 | H6: 0 | I6: =+G6-H6 -> 1440 | J6: =SUM(AF6:AK6) -> 104.29232 | K6: =SUM(AL6:AX6) -> 196 | L6: =+K6+J6 -> 300.29232 | M6: =+I6-L6 -> 1139.7077 | N6: 9212 | P6: 8187 | Q6: =SUM(N6:P6) -> 17399 | R6: =SUM(Z6:AD6) -> 2 | S6: =+Q6-R6 -> 17397 | T6: =IFERROR((M6*60)/E6,"-") -> 15902.898 | U6: =IFERROR(M6/I6," ") -> 0.79146367 | V6: =IFERROR(Q6/T6," ") -> 1.0940773 | W6: =IFERROR(S6/Q6," ") -> 0.99988505 | X6: =IFERROR(U6*V6*W6," ") -> 0.86582292 | Z6: 2 | AE6: =Table24[[#This Row],[H. จำนวนชิ้น งานทั้งหมด ที่ผลิตได้ (Total Count)]]/512*1 -> 33.982422 | AF6: =(Q6/512*68/60) -> 38.513411 | AG6: =(Q6/512*35/60) -> 19.823079 | AH6: =(Q6/512*37/60) -> 20.955827 | AI6: 10 | AJ6: 5 | AK6: 10 | AL6: =SUMIFS(Table1[Column1],Table1[Date],'OEE AHV'!$B6,Table1[M/C],'OEE AHV'!$D6,Table1[Case downtime],'OEE AHV'!AL$2) -> 25 | AM6: =SUMIFS(Table1[Column1],Table1[Date],'OEE AHV'!$B6,Table1[M/C],'OEE AHV'!$D6,Table1[Case downtime],'OEE AHV'!AM$2) -> 0 | AN6: =SUMIFS(Table1[Column1],Table1[Date],'OEE AHV'!$B6,Table1[M/C],'OEE AHV'!$D6,Table1[Case downtime],'OEE AHV'!AN$2) -> 0 | AO6: =SUMIFS(Table1[Column1],Table1[Date],'OEE AHV'!$B6,Table1[M/C],'OEE AHV'!$D6,Table1[Case downtime],'OEE AHV'!AO$2) -> 0 | AP6: =SUMIFS(Table1[Column1],Table1[Date],'OEE AHV'!$B6,Table1[M/C],'OEE AHV'!$D6,Table1[Case downtime],'OEE AHV'!AP$2) -> 0 | AQ6: =SUMIFS(Table1[Column1],Table1[Date],'OEE AHV'!$B6,Table1[M/C],'OEE AHV'!$D6,Table1[Case downtime],'OEE AHV'!AQ$2) -> 0 | AR6: =SUMIFS(Table1[Column1],Table1[Date],'OEE AHV'!$B6,Table1[M/C],'OEE AHV'!$D6,Table1[Case downtime],'OEE AHV'!AR$2) -> 0 | AS6: =SUMIFS(Table1[Column1],Table1[Date],'OEE AHV'!$B6,Table1[M/C],'OEE AHV'!$D6,Table1[Case downtime],'OEE AHV'!AS$2) -> 0 | ... AX6: =SUMIFS(Table1[Column1],Table1[Date],'OEE AHV'!$B6,Table1[M/C],'OEE AHV'!$D6,Table1[Case downtime],'OEE AHV'!AX$2) -> 0
B7: 46059 | C7: DRD | D7: AHV-01 | E7: 4.3 | F7: 24 | G7: =F7*60 -> 1440 | H7: 0 | I7: =+G7-H7 -> 1440 | J7: =SUM(AF7:AK7) -> 97.310547 | K7: =SUM(AL7:AX7) -> 278 | L7: =+K7+J7 -> 375.31055 | M7: =+I7-L7 -> 1064.6895 | N7: 7676 | P7: 8191 | Q7: =SUM(N7:P7) -> 15867 | R7: =SUM(Z7:AD7) -> 1 | S7: =+Q7-R7 -> 15866 | T7: =IFERROR((M7*60)/E7,"-") -> 14856.132 | U7: =IFERROR(M7/I7," ") -> 0.73936768 | V7: =IFERROR(Q7/T7," ") -> 1.0680438 | W7: =IFERROR(S7/Q7," ") -> 0.99993698 | X7: =IFERROR(U7*V7*W7," ") -> 0.78962731 | Z7: 1 | AE7: =Table24[[#This Row],[H. จำนวนชิ้น งานทั้งหมด ที่ผลิตได้ (Total Count)]]/512*1 -> 30.990234 | AF7: =(Q7/512*68/60) -> 35.122266 | AG7: =(Q7/512*35/60) -> 18.077637 | AH7: =(Q7/512*37/60) -> 19.110645 | AI7: 10 | AJ7: 5 | AK7: 10 | AL7: =SUMIFS(Table1[Column1],Table1[Date],'OEE AHV'!$B7,Table1[M/C],'OEE AHV'!$D7,Table1[Case downtime],'OEE AHV'!AL$2) -> 0 | AM7: =SUMIFS(Table1[Column1],Table1[Date],'OEE AHV'!$B7,Table1[M/C],'OEE AHV'!$D7,Table1[Case downtime],'OEE AHV'!AM$2) -> 0 | AN7: =SUMIFS(Table1[Column1],Table1[Date],'OEE AHV'!$B7,Table1[M/C],'OEE AHV'!$D7,Table1[Case downtime],'OEE AHV'!AN$2) -> 0 | AO7: =SUMIFS(Table1[Column1],Table1[Date],'OEE AHV'!$B7,Table1[M/C],'OEE AHV'!$D7,Table1[Case downtime],'OEE AHV'!AO$2) -> 0 | AP7: =SUMIFS(Table1[Column1],Table1[Date],'OEE AHV'!$B7,Table1[M/C],'OEE AHV'!$D7,Table1[Case downtime],'OEE AHV'!AP$2) -> 0 | AQ7: =SUMIFS(Table1[Column1],Table1[Date],'OEE AHV'!$B7,Table1[M/C],'OEE AHV'!$D7,Table1[Case downtime],'OEE AHV'!AQ$2) -> 0 | AR7: =SUMIFS(Table1[Column1],Table1[Date],'OEE AHV'!$B7,Table1[M/C],'OEE AHV'!$D7,Table1[Case downtime],'OEE AHV'!AR$2) -> 0 | AS7: =SUMIFS(Table1[Column1],Table1[Date],'OEE AHV'!$B7,Table1[M/C],'OEE AHV'!$D7,Table1[Case downtime],'OEE AHV'!AS$2) -> 0 | ... AX7: =SUMIFS(Table1[Column1],Table1[Date],'OEE AHV'!$B7,Table1[M/C],'OEE AHV'!$D7,Table1[Case downtime],'OEE AHV'!AX$2) -> 0
B8: 46060 | C8: DRD | D8: AHV-01 | E8: 4.3 | F8: 24 | G8: =F8*60 -> 1440 | H8: 0 | I8: =+G8-H8 -> 1440 | J8: =SUM(AF8:AK8) -> 106.59375 | K8: =SUM(AL8:AX8) -> 45 | L8: =+K8+J8 -> 151.59375 | M8: =+I8-L8 -> 1288.4062 | N8: 9208 | P8: 8696 | Q8: =SUM(N8:P8) -> 17904 | R8: =SUM(Z8:AD8) -> 0 | S8: =+Q8-R8 -> 17904 | T8: =IFERROR((M8*60)/E8,"-") -> 17977.762 | U8: =IFERROR(M8/I8," ") -> 0.89472656 | V8: =IFERROR(Q8/T8," ") -> 0.99589706 | W8: =IFERROR(S8/Q8," ") -> 1 | X8: =IFERROR(U8*V8*W8," ") -> 0.89105556 | Z8: 0 | AE8: =Table24[[#This Row],[H. จำนวนชิ้น งานทั้งหมด ที่ผลิตได้ (Total Count)]]/512*1 -> 34.96875 | AF8: =(Q8/512*68/60) -> 39.63125 | AG8: =(Q8/512*35/60) -> 20.398438 | AH8: =(Q8/512*37/60) -> 21.564062 | AI8: 10 | AJ8: 5 | AK8: 10 | AL8: =SUMIFS(Table1[Column1],Table1[Date],'OEE AHV'!$B8,Table1[M/C],'OEE AHV'!$D8,Table1[Case downtime],'OEE AHV'!AL$2) -> 0 | AM8: =SUMIFS(Table1[Column1],Table1[Date],'OEE AHV'!$B8,Table1[M/C],'OEE AHV'!$D8,Table1[Case downtime],'OEE AHV'!AM$2) -> 0 | AN8: =SUMIFS(Table1[Column1],Table1[Date],'OEE AHV'!$B8,Table1[M/C],'OEE AHV'!$D8,Table1[Case downtime],'OEE AHV'!AN$2) -> 0 | AO8: =SUMIFS(Table1[Column1],Table1[Date],'OEE AHV'!$B8,Table1[M/C],'OEE AHV'!$D8,Table1[Case downtime],'OEE AHV'!AO$2) -> 0 | AP8: =SUMIFS(Table1[Column1],Table1[Date],'OEE AHV'!$B8,Table1[M/C],'OEE AHV'!$D8,Table1[Case downtime],'OEE AHV'!AP$2) -> 0 | AQ8: =SUMIFS(Table1[Column1],Table1[Date],'OEE AHV'!$B8,Table1[M/C],'OEE AHV'!$D8,Table1[Case downtime],'OEE AHV'!AQ$2) -> 0 | AR8: =SUMIFS(Table1[Column1],Table1[Date],'OEE AHV'!$B8,Table1[M/C],'OEE AHV'!$D8,Table1[Case downtime],'OEE AHV'!AR$2) -> 0 | AS8: =SUMIFS(Table1[Column1],Table1[Date],'OEE AHV'!$B8,Table1[M/C],'OEE AHV'!$D8,Table1[Case downtime],'OEE AHV'!AS$2) -> 0 | ... AX8: =SUMIFS(Table1[Column1],Table1[Date],'OEE AHV'!$B8,Table1[M/C],'OEE AHV'!$D8,Table1[Case downtime],'OEE AHV'!AX$2) -> 0
B9: 46061 | C9: DRD | D9: AHV-01 | E9: 4.3 | F9: 12 | G9: =F9*60 -> 720 | H9: 0 | I9: =+G9-H9 -> 720 | J9: =SUM(AF9:AK9) -> 55.296875 | K9: =SUM(AL9:AX9) -> 0 | L9: =+K9+J9 -> 55.296875 | M9: =+I9-L9 -> 664.70312 | N9: 0 | P9: 6648 | Q9: =SUM(N9:P9) -> 6648 | R9: =SUM(Z9:AD9) -> 0 | S9: =+Q9-R9 -> 6648 | T9: =IFERROR((M9*60)/E9,"-") -> 9274.9273 | U9: =IFERROR(M9/I9," ") -> 0.92319878 | V9: =IFERROR(Q9/T9," ") -> 0.71677111 | W9: =IFERROR(S9/Q9," ") -> 1 | X9: =IFERROR(U9*V9*W9," ") -> 0.66172222 | Z9: 0 | AE9: =Table24[[#This Row],[H. จำนวนชิ้น งานทั้งหมด ที่ผลิตได้ (Total Count)]]/512*1 -> 12.984375 | AF9: =(Q9/512*68/60) -> 14.715625 | AG9: =(Q9/512*35/60) -> 7.5742188 | AH9: =(Q9/512*37/60) -> 8.0070313 | AI9: 10 | AJ9: 5 | AK9: 10 | AL9: =SUMIFS(Table1[Column1],Table1[Date],'OEE AHV'!$B9,Table1[M/C],'OEE AHV'!$D9,Table1[Case downtime],'OEE AHV'!AL$2) -> 0 | AM9: =SUMIFS(Table1[Column1],Table1[Date],'OEE AHV'!$B9,Table1[M/C],'OEE AHV'!$D9,Table1[Case downtime],'OEE AHV'!AM$2) -> 0 | AN9: =SUMIFS(Table1[Column1],Table1[Date],'OEE AHV'!$B9,Table1[M/C],'OEE AHV'!$D9,Table1[Case downtime],'OEE AHV'!AN$2) -> 0 | AO9: =SUMIFS(Table1[Column1],Table1[Date],'OEE AHV'!$B9,Table1[M/C],'OEE AHV'!$D9,Table1[Case downtime],'OEE AHV'!AO$2) -> 0 | AP9: =SUMIFS(Table1[Column1],Table1[Date],'OEE AHV'!$B9,Table1[M/C],'OEE AHV'!$D9,Table1[Case downtime],'OEE AHV'!AP$2) -> 0 | AQ9: =SUMIFS(Table1[Column1],Table1[Date],'OEE AHV'!$B9,Table1[M/C],'OEE AHV'!$D9,Table1[Case downtime],'OEE AHV'!AQ$2) -> 0 | AR9: =SUMIFS(Table1[Column1],Table1[Date],'OEE AHV'!$B9,Table1[M/C],'OEE AHV'!$D9,Table1[Case downtime],'OEE AHV'!AR$2) -> 0 | AS9: =SUMIFS(Table1[Column1],Table1[Date],'OEE AHV'!$B9,Table1[M/C],'OEE AHV'!$D9,Table1[Case downtime],'OEE AHV'!AS$2) -> 0 | ... AX9: =SUMIFS(Table1[Column1],Table1[Date],'OEE AHV'!$B9,Table1[M/C],'OEE AHV'!$D9,Table1[Case downtime],'OEE AHV'!AX$2) -> 0
B10: 46062 | C10: DRD | D10: AHV-01 | E10: 4.3 | F10: 24 | G10: =F10*60 -> 1440 | H10: 0 | I10: =+G10-H10 -> 1440 | J10: =SUM(AF10:AK10) -> 108.92708 | K10: =SUM(AL10:AX10) -> 32 | L10: =+K10+J10 -> 140.92708 | M10: =+I10-L10 -> 1299.0729 | N10: 9208 | P10: 9208 | Q10: =SUM(N10:P10) -> 18416 | R10: =SUM(Z10:AD10) -> 2 | S10: =+Q10-R10 -> 18414 | T10: =IFERROR((M10*60)/E10,"-") -> 18126.599 | U10: =IFERROR(M10/I10," ") -> 0.90213397 | V10: =IFERROR(Q10/T10," ") -> 1.0159656 | W10: =IFERROR(S10/Q10," ") -> 0.9998914 | X10: =IFERROR(U10*V10*W10," ") -> 0.9164375 | Z10: 2 | AE10: =Table24[[#This Row],[H. จำนวนชิ้น งานทั้งหมด ที่ผลิตได้ (Total Count)]]/512*1 -> 35.96875 | AF10: =(Q10/512*68/60) -> 40.764583 | AG10: =(Q10/512*35/60) -> 20.981771 | AH10: =(Q10/512*37/60) -> 22.180729 | AI10: 10 | AJ10: 5 | AK10: 10 | AL10: =SUMIFS(Table1[Column1],Table1[Date],'OEE AHV'!$B10,Table1[M/C],'OEE AHV'!$D10,Table1[Case downtime],'OEE AHV'!AL$2) -> 0 | AM10: =SUMIFS(Table1[Column1],Table1[Date],'OEE AHV'!$B10,Table1[M/C],'OEE AHV'!$D10,Table1[Case downtime],'OEE AHV'!AM$2) -> 0 | AN10: =SUMIFS(Table1[Column1],Table1[Date],'OEE AHV'!$B10,Table1[M/C],'OEE AHV'!$D10,Table1[Case downtime],'OEE AHV'!AN$2) -> 0 | AO10: =SUMIFS(Table1[Column1],Table1[Date],'OEE AHV'!$B10,Table1[M/C],'OEE AHV'!$D10,Table1[Case downtime],'OEE AHV'!AO$2) -> 0 | AP10: =SUMIFS(Table1[Column1],Table1[Date],'OEE AHV'!$B10,Table1[M/C],'OEE AHV'!$D10,Table1[Case downtime],'OEE AHV'!AP$2) -> 0 | AQ10: =SUMIFS(Table1[Column1],Table1[Date],'OEE AHV'!$B10,Table1[M/C],'OEE AHV'!$D10,Table1[Case downtime],'OEE AHV'!AQ$2) -> 0 | AR10: =SUMIFS(Table1[Column1],Table1[Date],'OEE AHV'!$B10,Table1[M/C],'OEE AHV'!$D10,Table1[Case downtime],'OEE AHV'!AR$2) -> 0 | AS10: =SUMIFS(Table1[Column1],Table1[Date],'OEE AHV'!$B10,Table1[M/C],'OEE AHV'!$D10,Table1[Case downtime],'OEE AHV'!AS$2) -> 0 | ... AX10: =SUMIFS(Table1[Column1],Table1[Date],'OEE AHV'!$B10,Table1[M/C],'OEE AHV'!$D10,Table1[Case downtime],'OEE AHV'!AX$2) -> 0
B11: 46063 | C11: DRD | D11: AHV-01 | E11: 4.3 | F11: 24 | G11: =F11*60 -> 1440 | H11: 0 | I11: =+G11-H11 -> 1440 | J11: =SUM(AF11:AK11) -> 106.62565 | K11: =SUM(AL11:AX11) -> 103 | L11: =+K11+J11 -> 209.62565 | M11: =+I11-L11 -> 1230.3743 | N11: 8700 | P11: 9211 | Q11: =SUM(N11:P11) -> 17911 | R11: =SUM(Z11:AD11) -> 1 | S11: =+Q11-R11 -> 17910 | T11: =IFERROR((M11*60)/E11,"-") -> 17168.014 | U11: =IFERROR(M11/I11," ") -> 0.85442663 | V11: =IFERROR(Q11/T11," ") -> 1.0432773 | W11: =IFERROR(S11/Q11," ") -> 0.99994417 | X11: =IFERROR(U11*V11*W11," ") -> 0.89135417 | Z11: 1 | AE11: =Table24[[#This Row],[H. จำนวนชิ้น งานทั้งหมด ที่ผลิตได้ (Total Count)]]/512*1 -> 34.982422 | AF11: =(Q11/512*68/60) -> 39.646745 | AG11: =(Q11/512*35/60) -> 20.406413 | AH11: =(Q11/512*37/60) -> 21.572493 | AI11: 10 | AJ11: 5 | AK11: 10 | AL11: =SUMIFS(Table1[Column1],Table1[Date],'OEE AHV'!$B11,Table1[M/C],'OEE AHV'!$D11,Table1[Case downtime],'OEE AHV'!AL$2) -> 39 | AM11: =SUMIFS(Table1[Column1],Table1[Date],'OEE AHV'!$B11,Table1[M/C],'OEE AHV'!$D11,Table1[Case downtime],'OEE AHV'!AM$2) -> 0 | AN11: =SUMIFS(Table1[Column1],Table1[Date],'OEE AHV'!$B11,Table1[M/C],'OEE AHV'!$D11,Table1[Case downtime],'OEE AHV'!AN$2) -> 0 | AO11: =SUMIFS(Table1[Column1],Table1[Date],'OEE AHV'!$B11,Table1[M/C],'OEE AHV'!$D11,Table1[Case downtime],'OEE AHV'!AO$2) -> 0 | AP11: =SUMIFS(Table1[Column1],Table1[Date],'OEE AHV'!$B11,Table1[M/C],'OEE AHV'!$D11,Table1[Case downtime],'OEE AHV'!AP$2) -> 0 | AQ11: =SUMIFS(Table1[Column1],Table1[Date],'OEE AHV'!$B11,Table1[M/C],'OEE AHV'!$D11,Table1[Case downtime],'OEE AHV'!AQ$2) -> 0 | AR11: =SUMIFS(Table1[Column1],Table1[Date],'OEE AHV'!$B11,Table1[M/C],'OEE AHV'!$D11,Table1[Case downtime],'OEE AHV'!AR$2) -> 0 | AS11: =SUMIFS(Table1[Column1],Table1[Date],'OEE AHV'!$B11,Table1[M/C],'OEE AHV'!$D11,Table1[Case downtime],'OEE AHV'!AS$2) -> 0 | ... AX11: =SUMIFS(Table1[Column1],Table1[Date],'OEE AHV'!$B11,Table1[M/C],'OEE AHV'!$D11,Table1[Case downtime],'OEE AHV'!AX$2) -> 0
B12: 46064 | C12: DRD | D12: AHV-01 | E12: 4.3 | F12: 24 | G12: =F12*60 -> 1440 | H12: 0 | I12: =+G12-H12 -> 1440 | J12: =SUM(AF12:AK12) -> 111.27865 | K12: =SUM(AL12:AX12) -> 0 | L12: =+K12+J12 -> 111.27865 | M12: =+I12-L12 -> 1328.7214 | N12: 9212 | P12: 9720 | Q12: =SUM(N12:P12) -> 18932 | R12: =SUM(Z12:AD12) -> 0 | S12: =+Q12-R12 -> 18932 | T12: =IFERROR((M12*60)/E12,"-") -> 18540.298 | U12: =IFERROR(M12/I12," ") -> 0.92272316 | V12: =IFERROR(Q12/T12," ") -> 1.0211271 | W12: =IFERROR(S12/Q12," ") -> 1 | X12: =IFERROR(U12*V12*W12," ") -> 0.94221759 | Z12: 0 | AE12: =Table24[[#This Row],[H. จำนวนชิ้น งานทั้งหมด ที่ผลิตได้ (Total Count)]]/512*1 -> 36.976562 | AF12: =(Q12/512*68/60) -> 41.906771 | AG12: =(Q12/512*35/60) -> 21.569661 | AH12: =(Q12/512*37/60) -> 22.802214 | AI12: 10 | AJ12: 5 | AK12: 10 | AL12: =SUMIFS(Table1[Column1],Table1[Date],'OEE AHV'!$B12,Table1[M/C],'OEE AHV'!$D12,Table1[Case downtime],'OEE AHV'!AL$2) -> 0 | AM12: =SUMIFS(Table1[Column1],Table1[Date],'OEE AHV'!$B12,Table1[M/C],'OEE AHV'!$D12,Table1[Case downtime],'OEE AHV'!AM$2) -> 0 | AN12: =SUMIFS(Table1[Column1],Table1[Date],'OEE AHV'!$B12,Table1[M/C],'OEE AHV'!$D12,Table1[Case downtime],'OEE AHV'!AN$2) -> 0 | AO12: =SUMIFS(Table1[Column1],Table1[Date],'OEE AHV'!$B12,Table1[M/C],'OEE AHV'!$D12,Table1[Case downtime],'OEE AHV'!AO$2) -> 0 | AP12: =SUMIFS(Table1[Column1],Table1[Date],'OEE AHV'!$B12,Table1[M/C],'OEE AHV'!$D12,Table1[Case downtime],'OEE AHV'!AP$2) -> 0 | AQ12: =SUMIFS(Table1[Column1],Table1[Date],'OEE AHV'!$B12,Table1[M/C],'OEE AHV'!$D12,Table1[Case downtime],'OEE AHV'!AQ$2) -> 0 | AR12: =SUMIFS(Table1[Column1],Table1[Date],'OEE AHV'!$B12,Table1[M/C],'OEE AHV'!$D12,Table1[Case downtime],'OEE AHV'!AR$2) -> 0 | AS12: =SUMIFS(Table1[Column1],Table1[Date],'OEE AHV'!$B12,Table1[M/C],'OEE AHV'!$D12,Table1[Case downtime],'OEE AHV'!AS$2) -> 0 | ... AX12: =SUMIFS(Table1[Column1],Table1[Date],'OEE AHV'!$B12,Table1[M/C],'OEE AHV'!$D12,Table1[Case downtime],'OEE AHV'!AX$2) -> 0
B13: 46065 | C13: DRD | D13: AHV-01 | E13: 4.3 | F13: 24 | G13: =F13*60 -> 1440 | H13: 0 | I13: =+G13-H13 -> 1440 | J13: =SUM(AF13:AK13) -> 111.22396 | K13: =SUM(AL13:AX13) -> 0 | L13: =+K13+J13 -> 111.22396 | M13: =+I13-L13 -> 1328.776 | N13: 9207 | P13: 9713 | Q13: =SUM(N13:P13) -> 18920 | R13: =SUM(Z13:AD13) -> 6 | S13: =+Q13-R13 -> 18914 | T13: =IFERROR((M13*60)/E13,"-") -> 18541.061 | U13: =IFERROR(M13/I13," ") -> 0.92276114 | V13: =IFERROR(Q13/T13," ") -> 1.0204378 | W13: =IFERROR(S13/Q13," ") -> 0.99968288 | X13: =IFERROR(U13*V13*W13," ") -> 0.94132176 | Z13: 6 | AE13: =Table24[[#This Row],[H. จำนวนชิ้น งานทั้งหมด ที่ผลิตได้ (Total Count)]]/512*1 -> 36.953125 | AF13: =(Q13/512*68/60) -> 41.880208 | AG13: =(Q13/512*35/60) -> 21.55599 | AH13: =(Q13/512*37/60) -> 22.78776 | AI13: 10 | AJ13: 5 | AK13: 10 | AL13: =SUMIFS(Table1[Column1],Table1[Date],'OEE AHV'!$B13,Table1[M/C],'OEE AHV'!$D13,Table1[Case downtime],'OEE AHV'!AL$2) -> 0 | AM13: =SUMIFS(Table1[Column1],Table1[Date],'OEE AHV'!$B13,Table1[M/C],'OEE AHV'!$D13,Table1[Case downtime],'OEE AHV'!AM$2) -> 0 | AN13: =SUMIFS(Table1[Column1],Table1[Date],'OEE AHV'!$B13,Table1[M/C],'OEE AHV'!$D13,Table1[Case downtime],'OEE AHV'!AN$2) -> 0 | AO13: =SUMIFS(Table1[Column1],Table1[Date],'OEE AHV'!$B13,Table1[M/C],'OEE AHV'!$D13,Table1[Case downtime],'OEE AHV'!AO$2) -> 0 | AP13: =SUMIFS(Table1[Column1],Table1[Date],'OEE AHV'!$B13,Table1[M/C],'OEE AHV'!$D13,Table1[Case downtime],'OEE AHV'!AP$2) -> 0 | AQ13: =SUMIFS(Table1[Column1],Table1[Date],'OEE AHV'!$B13,Table1[M/C],'OEE AHV'!$D13,Table1[Case downtime],'OEE AHV'!AQ$2) -> 0 | AR13: =SUMIFS(Table1[Column1],Table1[Date],'OEE AHV'!$B13,Table1[M/C],'OEE AHV'!$D13,Table1[Case downtime],'OEE AHV'!AR$2) -> 0 | AS13: =SUMIFS(Table1[Column1],Table1[Date],'OEE AHV'!$B13,Table1[M/C],'OEE AHV'!$D13,Table1[Case downtime],'OEE AHV'!AS$2) -> 0 | ... AX13: =SUMIFS(Table1[Column1],Table1[Date],'OEE AHV'!$B13,Table1[M/C],'OEE AHV'!$D13,Table1[Case downtime],'OEE AHV'!AX$2) -> 0
B14: 46066 | C14: DRD | D14: AHV-01 | E14: 4.3 | F14: 24 | G14: =F14*60 -> 1440 | H14: 0 | I14: =+G14-H14 -> 1440 | J14: =SUM(AF14:AK14) -> 108.92253 | K14: =SUM(AL14:AX14) -> 20 | L14: =+K14+J14 -> 128.92253 | M14: =+I14-L14 -> 1311.0775 | N14: 9206 | P14: 9209 | Q14: =SUM(N14:P14) -> 18415 | R14: =SUM(Z14:AD14) -> 0 | S14: =+Q14-R14 -> 18415 | T14: =IFERROR((M14*60)/E14,"-") -> 18294.104 | U14: =IFERROR(M14/I14," ") -> 0.91047047 | V14: =IFERROR(Q14/T14," ") -> 1.0066085 | W14: =IFERROR(S14/Q14," ") -> 1 | X14: =IFERROR(U14*V14*W14," ") -> 0.91648727 | Z14: 0 | AE14: =Table24[[#This Row],[H. จำนวนชิ้น งานทั้งหมด ที่ผลิตได้ (Total Count)]]/512*1 -> 35.966797 | AF14: =(Q14/512*68/60) -> 40.76237 | AG14: =(Q14/512*35/60) -> 20.980632 | AH14: =(Q14/512*37/60) -> 22.179525 | AI14: 10 | AJ14: 5 | AK14: 10 | AL14: =SUMIFS(Table1[Column1],Table1[Date],'OEE AHV'!$B14,Table1[M/C],'OEE AHV'!$D14,Table1[Case downtime],'OEE AHV'!AL$2) -> 20 | AM14: =SUMIFS(Table1[Column1],Table1[Date],'OEE AHV'!$B14,Table1[M/C],'OEE AHV'!$D14,Table1[Case downtime],'OEE AHV'!AM$2) -> 0 | AN14: =SUMIFS(Table1[Column1],Table1[Date],'OEE AHV'!$B14,Table1[M/C],'OEE AHV'!$D14,Table1[Case downtime],'OEE AHV'!AN$2) -> 0 | AO14: =SUMIFS(Table1[Column1],Table1[Date],'OEE AHV'!$B14,Table1[M/C],'OEE AHV'!$D14,Table1[Case downtime],'OEE AHV'!AO$2) -> 0 | AP14: =SUMIFS(Table1[Column1],Table1[Date],'OEE AHV'!$B14,Table1[M/C],'OEE AHV'!$D14,Table1[Case downtime],'OEE AHV'!AP$2) -> 0 | AQ14: =SUMIFS(Table1[Column1],Table1[Date],'OEE AHV'!$B14,Table1[M/C],'OEE AHV'!$D14,Table1[Case downtime],'OEE AHV'!AQ$2) -> 0 | AR14: =SUMIFS(Table1[Column1],Table1[Date],'OEE AHV'!$B14,Table1[M/C],'OEE AHV'!$D14,Table1[Case downtime],'OEE AHV'!AR$2) -> 0 | AS14: =SUMIFS(Table1[Column1],Table1[Date],'OEE AHV'!$B14,Table1[M/C],'OEE AHV'!$D14,Table1[Case downtime],'OEE AHV'!AS$2) -> 0 | ... AX14: =SUMIFS(Table1[Column1],Table1[Date],'OEE AHV'!$B14,Table1[M/C],'OEE AHV'!$D14,Table1[Case downtime],'OEE AHV'!AX$2) -> 0
... B98: 46080 | C98: DRD | D98: AHV-04 | E98: 4.3 | F98: 24 | G98: =F98*60 -> 1440 | H98: 0 | I98: =+G98-H98 -> 1440 | J98: =SUM(AF98:AK98) -> 113.57552 | K98: =SUM(AL98:AX98) -> 0 | L98: =+K98+J98 -> 113.57552 | M98: =+I98-L98 -> 1326.4245 | N98: 9716 | P98: 9720 | Q98: =SUM(N98:P98) -> 19436 | R98: =SUM(Z98:AD98) -> 1 | S98: =+Q98-R98 -> 19435 | T98: =IFERROR((M98*60)/E98,"-") -> 18508.249 | U98: =IFERROR(M98/I98," ") -> 0.92112811 | V98: =IFERROR(Q98/T98," ") -> 1.0501264 | W98: =IFERROR(S98/Q98," ") -> 0.99994855 | X98: =IFERROR(U98*V98*W98," ") -> 0.96725116 | Z98: 1 | AE98: =Table24[[#This Row],[H. จำนวนชิ้น งานทั้งหมด ที่ผลิตได้ (Total Count)]]/512*1 -> 37.960938 | AF98: =(Q98/512*68/60) -> 43.022396 | AG98: =(Q98/512*35/60) -> 22.14388 | AH98: =(Q98/512*37/60) -> 23.409245 | AI98: 10 | AJ98: 5 | AK98: 10 | AL98: =SUMIFS(Table1[Column1],Table1[Date],'OEE AHV'!$B98,Table1[M/C],'OEE AHV'!$D98,Table1[Case downtime],'OEE AHV'!AL$2) -> 0 | AM98: =SUMIFS(Table1[Column1],Table1[Date],'OEE AHV'!$B98,Table1[M/C],'OEE AHV'!$D98,Table1[Case downtime],'OEE AHV'!AM$2) -> 0 | AN98: =SUMIFS(Table1[Column1],Table1[Date],'OEE AHV'!$B98,Table1[M/C],'OEE AHV'!$D98,Table1[Case downtime],'OEE AHV'!AN$2) -> 0 | AO98: =SUMIFS(Table1[Column1],Table1[Date],'OEE AHV'!$B98,Table1[M/C],'OEE AHV'!$D98,Table1[Case downtime],'OEE AHV'!AO$2) -> 0 | AP98: =SUMIFS(Table1[Column1],Table1[Date],'OEE AHV'!$B98,Table1[M/C],'OEE AHV'!$D98,Table1[Case downtime],'OEE AHV'!AP$2) -> 0 | AQ98: =SUMIFS(Table1[Column1],Table1[Date],'OEE AHV'!$B98,Table1[M/C],'OEE AHV'!$D98,Table1[Case downtime],'OEE AHV'!AQ$2) -> 0 | AR98: =SUMIFS(Table1[Column1],Table1[Date],'OEE AHV'!$B98,Table1[M/C],'OEE AHV'!$D98,Table1[Case downtime],'OEE AHV'!AR$2) -> 0 | AS98: =SUMIFS(Table1[Column1],Table1[Date],'OEE AHV'!$B98,Table1[M/C],'OEE AHV'!$D98,Table1[Case downtime],'OEE AHV'!AS$2) -> 0 | ... AX98: =SUMIFS(Table1[Column1],Table1[Date],'OEE AHV'!$B98,Table1[M/C],'OEE AHV'!$D98,Table1[Case downtime],'OEE AHV'!AX$2) -> 0
B99: 46055 | C99: DRD | D99: AHV-05 | E99: 4.3 | F99: 24 | G99: =F99*60 -> 1440 | H99: 0 | I99: =+G99-H99 -> 1440 | J99: =SUM(AF99:AK99) -> 73.954427 | K99: =SUM(AL99:AX99) -> 637 | L99: =+K99+J99 -> 710.95443 | M99: =+I99-L99 -> 729.04557 | N99: 2558 | P99: 8184 | Q99: =SUM(N99:P99) -> 10742 | R99: =SUM(Z99:AD99) -> 0 | S99: =+Q99-R99 -> 10742 | T99: =IFERROR((M99*60)/E99,"-") -> 10172.729 | U99: =IFERROR(M99/I99," ") -> 0.50628165 | V99: =IFERROR(Q99/T99," ") -> 1.0559605 | W99: =IFERROR(S99/Q99," ") -> 1 | X99: =IFERROR(U99*V99*W99," ") -> 0.53461343 | Z99: 0 | AE99: =$AE$98 -> 37.960938 | AF99: =(Q99/512*68/60) -> 23.777865 | AG99: =(Q99/512*35/60) -> 12.238607 | AH99: =(Q99/512*37/60) -> 12.937956 | AI99: 10 | AJ99: 5 | AK99: 10 | AL99: =SUMIFS(Table1[Column1],Table1[Date],'OEE AHV'!$B99,Table1[M/C],'OEE AHV'!$D99,Table1[Case downtime],'OEE AHV'!AL$2) -> 0 | AM99: =SUMIFS(Table1[Column1],Table1[Date],'OEE AHV'!$B99,Table1[M/C],'OEE AHV'!$D99,Table1[Case downtime],'OEE AHV'!AM$2) -> 0 | AN99: =SUMIFS(Table1[Column1],Table1[Date],'OEE AHV'!$B99,Table1[M/C],'OEE AHV'!$D99,Table1[Case downtime],'OEE AHV'!AN$2) -> 0 | AO99: =SUMIFS(Table1[Column1],Table1[Date],'OEE AHV'!$B99,Table1[M/C],'OEE AHV'!$D99,Table1[Case downtime],'OEE AHV'!AO$2) -> 0 | AP99: =SUMIFS(Table1[Column1],Table1[Date],'OEE AHV'!$B99,Table1[M/C],'OEE AHV'!$D99,Table1[Case downtime],'OEE AHV'!AP$2) -> 0 | AQ99: =SUMIFS(Table1[Column1],Table1[Date],'OEE AHV'!$B99,Table1[M/C],'OEE AHV'!$D99,Table1[Case downtime],'OEE AHV'!AQ$2) -> 0 | AR99: =SUMIFS(Table1[Column1],Table1[Date],'OEE AHV'!$B99,Table1[M/C],'OEE AHV'!$D99,Table1[Case downtime],'OEE AHV'!AR$2) -> 0 | AS99: =SUMIFS(Table1[Column1],Table1[Date],'OEE AHV'!$B99,Table1[M/C],'OEE AHV'!$D99,Table1[Case downtime],'OEE AHV'!AS$2) -> 0 | ... AX99: =SUMIFS(Table1[Column1],Table1[Date],'OEE AHV'!$B99,Table1[M/C],'OEE AHV'!$D99,Table1[Case downtime],'OEE AHV'!AX$2) -> 0
B100: 46056 | C100: DRD | D100: AHV-05 | E100: 4.3 | F100: 24 | G100: =F100*60 -> 1440 | H100: 0 | I100: =+G100-H100 -> 1440 | J100: =SUM(AF100:AK100) -> 71.625651 | K100: =SUM(AL100:AX100) -> 559 | L100: =+K100+J100 -> 630.62565 | M100: =+I100-L100 -> 809.37435 | N100: 4604 | P100: 5627 | Q100: =SUM(N100:P100) -> 10231 | R100: =SUM(Z100:AD100) -> 0 | S100: =+Q100-R100 -> 10231 | T100: =IFERROR((M100*60)/E100,"-") -> 11293.596 | U100: =IFERROR(M100/I100," ") -> 0.56206552 | V100: =IFERROR(Q100/T100," ") -> 0.90591167 | W100: =IFERROR(S100/Q100," ") -> 1 | X100: =IFERROR(U100*V100*W100," ") -> 0.50918171 | Z100: 0 | AE100: =$AE$98 -> 37.960938 | AF100: =(Q100/512*68/60) -> 22.646745 | AG100: =(Q100/512*35/60) -> 11.656413 | AH100: =(Q100/512*37/60) -> 12.322493 | AI100: 10 | AJ100: 5 | AK100: 10 | AL100: =SUMIFS(Table1[Column1],Table1[Date],'OEE AHV'!$B100,Table1[M/C],'OEE AHV'!$D100,Table1[Case downtime],'OEE AHV'!AL$2) -> 235 | AM100: =SUMIFS(Table1[Column1],Table1[Date],'OEE AHV'!$B100,Table1[M/C],'OEE AHV'!$D100,Table1[Case downtime],'OEE AHV'!AM$2) -> 0 | AN100: =SUMIFS(Table1[Column1],Table1[Date],'OEE AHV'!$B100,Table1[M/C],'OEE AHV'!$D100,Table1[Case downtime],'OEE AHV'!AN$2) -> 0 | AO100: =SUMIFS(Table1[Column1],Table1[Date],'OEE AHV'!$B100,Table1[M/C],'OEE AHV'!$D100,Table1[Case downtime],'OEE AHV'!AO$2) -> 0 | AP100: =SUMIFS(Table1[Column1],Table1[Date],'OEE AHV'!$B100,Table1[M/C],'OEE AHV'!$D100,Table1[Case downtime],'OEE AHV'!AP$2) -> 0 | AQ100: =SUMIFS(Table1[Column1],Table1[Date],'OEE AHV'!$B100,Table1[M/C],'OEE AHV'!$D100,Table1[Case downtime],'OEE AHV'!AQ$2) -> 0 | AR100: =SUMIFS(Table1[Column1],Table1[Date],'OEE AHV'!$B100,Table1[M/C],'OEE AHV'!$D100,Table1[Case downtime],'OEE AHV'!AR$2) -> 0 | AS100: =SUMIFS(Table1[Column1],Table1[Date],'OEE AHV'!$B100,Table1[M/C],'OEE AHV'!$D100,Table1[Case downtime],'OEE AHV'!AS$2) -> 0 | ... AX100: =SUMIFS(Table1[Column1],Table1[Date],'OEE AHV'!$B100,Table1[M/C],'OEE AHV'!$D100,Table1[Case downtime],'OEE AHV'!AX$2) -> 0
B101: 46057 | C101: DRD | D101: AHV-05 | E101: 4.3 | F101: 24 | G101: =F101*60 -> 1440 | H101: 0 | I101: =+G101-H101 -> 1440 | J101: =SUM(AF101:AK101) -> 97.260417 | K101: =SUM(AL101:AX101) -> 65 | L101: =+K101+J101 -> 162.26042 | M101: =+I101-L101 -> 1277.7396 | N101: 7160 | P101: 8696 | Q101: =SUM(N101:P101) -> 15856 | R101: =SUM(Z101:AD101) -> 0 | S101: =+Q101-R101 -> 15856 | T101: =IFERROR((M101*60)/E101,"-") -> 17828.924 | U101: =IFERROR(M101/I101," ") -> 0.88731916 | V101: =IFERROR(Q101/T101," ") -> 0.88934137 | W101: =IFERROR(S101/Q101," ") -> 1 | X101: =IFERROR(U101*V101*W101," ") -> 0.78912963 | Z101: 0 | AE101: =$AE$98 -> 37.960938 | AF101: =(Q101/512*68/60) -> 35.097917 | AG101: =(Q101/512*35/60) -> 18.065104 | AH101: =(Q101/512*37/60) -> 19.097396 | AI101: 10 | AJ101: 5 | AK101: 10 | AL101: =SUMIFS(Table1[Column1],Table1[Date],'OEE AHV'!$B101,Table1[M/C],'OEE AHV'!$D101,Table1[Case downtime],'OEE AHV'!AL$2) -> 62 | AM101: =SUMIFS(Table1[Column1],Table1[Date],'OEE AHV'!$B101,Table1[M/C],'OEE AHV'!$D101,Table1[Case downtime],'OEE AHV'!AM$2) -> 3 | AN101: =SUMIFS(Table1[Column1],Table1[Date],'OEE AHV'!$B101,Table1[M/C],'OEE AHV'!$D101,Table1[Case downtime],'OEE AHV'!AN$2) -> 0 | AO101: =SUMIFS(Table1[Column1],Table1[Date],'OEE AHV'!$B101,Table1[M/C],'OEE AHV'!$D101,Table1[Case downtime],'OEE AHV'!AO$2) -> 0 | AP101: =SUMIFS(Table1[Column1],Table1[Date],'OEE AHV'!$B101,Table1[M/C],'OEE AHV'!$D101,Table1[Case downtime],'OEE AHV'!AP$2) -> 0 | AQ101: =SUMIFS(Table1[Column1],Table1[Date],'OEE AHV'!$B101,Table1[M/C],'OEE AHV'!$D101,Table1[Case downtime],'OEE AHV'!AQ$2) -> 0 | AR101: =SUMIFS(Table1[Column1],Table1[Date],'OEE AHV'!$B101,Table1[M/C],'OEE AHV'!$D101,Table1[Case downtime],'OEE AHV'!AR$2) -> 0 | AS101: =SUMIFS(Table1[Column1],Table1[Date],'OEE AHV'!$B101,Table1[M/C],'OEE AHV'!$D101,Table1[Case downtime],'OEE AHV'!AS$2) -> 0 | ... AX101: =SUMIFS(Table1[Column1],Table1[Date],'OEE AHV'!$B101,Table1[M/C],'OEE AHV'!$D101,Table1[Case downtime],'OEE AHV'!AX$2) -> 0
B102: 46058 | C102: DRD | D102: AHV-05 | E102: 4.3 | F102: 24 | G102: =F102*60 -> 1440 | H102: 0 | I102: =+G102-H102 -> 1440 | J102: =SUM(AF102:AK102) -> 104.29688 | K102: =SUM(AL102:AX102) -> 145 | L102: =+K102+J102 -> 249.29688 | M102: =+I102-L102 -> 1190.7031 | N102: 8188 | P102: 9212 | Q102: =SUM(N102:P102) -> 17400 | R102: =SUM(Z102:AD102) -> 2 | S102: =+Q102-R102 -> 17398 | T102: =IFERROR((M102*60)/E102,"-") -> 16614.462 | U102: =IFERROR(M102/I102," ") -> 0.82687717 | V102: =IFERROR(Q102/T102," ") -> 1.0472804 | W102: =IFERROR(S102/Q102," ") -> 0.99988506 | X102: =IFERROR(U102*V102*W102," ") -> 0.86587269 | Z102: 2 | AE102: =$AE$98 -> 37.960938 | AF102: =(Q102/512*68/60) -> 38.515625 | AG102: =(Q102/512*35/60) -> 19.824219 | AH102: =(Q102/512*37/60) -> 20.957031 | AI102: 10 | AJ102: 5 | AK102: 10 | AL102: =SUMIFS(Table1[Column1],Table1[Date],'OEE AHV'!$B102,Table1[M/C],'OEE AHV'!$D102,Table1[Case downtime],'OEE AHV'!AL$2) -> 65 | AM102: =SUMIFS(Table1[Column1],Table1[Date],'OEE AHV'!$B102,Table1[M/C],'OEE AHV'!$D102,Table1[Case downtime],'OEE AHV'!AM$2) -> 0 | AN102: =SUMIFS(Table1[Column1],Table1[Date],'OEE AHV'!$B102,Table1[M/C],'OEE AHV'!$D102,Table1[Case downtime],'OEE AHV'!AN$2) -> 5 | AO102: =SUMIFS(Table1[Column1],Table1[Date],'OEE AHV'!$B102,Table1[M/C],'OEE AHV'!$D102,Table1[Case downtime],'OEE AHV'!AO$2) -> 0 | AP102: =SUMIFS(Table1[Column1],Table1[Date],'OEE AHV'!$B102,Table1[M/C],'OEE AHV'!$D102,Table1[Case downtime],'OEE AHV'!AP$2) -> 0 | AQ102: =SUMIFS(Table1[Column1],Table1[Date],'OEE AHV'!$B102,Table1[M/C],'OEE AHV'!$D102,Table1[Case downtime],'OEE AHV'!AQ$2) -> 0 | AR102: =SUMIFS(Table1[Column1],Table1[Date],'OEE AHV'!$B102,Table1[M/C],'OEE AHV'!$D102,Table1[Case downtime],'OEE AHV'!AR$2) -> 0 | AS102: =SUMIFS(Table1[Column1],Table1[Date],'OEE AHV'!$B102,Table1[M/C],'OEE AHV'!$D102,Table1[Case downtime],'OEE AHV'!AS$2) -> 0 | ... AX102: =SUMIFS(Table1[Column1],Table1[Date],'OEE AHV'!$B102,Table1[M/C],'OEE AHV'!$D102,Table1[Case downtime],'OEE AHV'!AX$2) -> 0
B103: 46059 | C103: DRD | D103: AHV-05 | E103: 4.3 | F103: 24 | G103: =F103*60 -> 1440 | H103: 0 | I103: =+G103-H103 -> 1440 | J103: =SUM(AF103:AK103) -> 113.61198 | K103: =SUM(AL103:AX103) -> 0 | L103: =+K103+J103 -> 113.61198 | M103: =+I103-L103 -> 1326.388 | N103: 9720 | P103: 9724 | Q103: =SUM(N103:P103) -> 19444 | R103: =SUM(Z103:AD103) -> 1 | S103: =+Q103-R103 -> 19443 | T103: =IFERROR((M103*60)/E103,"-") -> 18507.74 | U103: =IFERROR(M103/I103," ") -> 0.92110279 | V103: =IFERROR(Q103/T103," ") -> 1.0505875 | W103: =IFERROR(S103/Q103," ") -> 0.99994857 | X103: =IFERROR(U103*V103*W103," ") -> 0.96764931 | Z103: 1 | AE103: =$AE$98 -> 37.960938 | AF103: =(Q103/512*68/60) -> 43.040104 | AG103: =(Q103/512*35/60) -> 22.152995 | AH103: =(Q103/512*37/60) -> 23.41888 | AI103: 10 | AJ103: 5 | AK103: 10 | AL103: =SUMIFS(Table1[Column1],Table1[Date],'OEE AHV'!$B103,Table1[M/C],'OEE AHV'!$D103,Table1[Case downtime],'OEE AHV'!AL$2) -> 0 | AM103: =SUMIFS(Table1[Column1],Table1[Date],'OEE AHV'!$B103,Table1[M/C],'OEE AHV'!$D103,Table1[Case downtime],'OEE AHV'!AM$2) -> 0 | AN103: =SUMIFS(Table1[Column1],Table1[Date],'OEE AHV'!$B103,Table1[M/C],'OEE AHV'!$D103,Table1[Case downtime],'OEE AHV'!AN$2) -> 0 | AO103: =SUMIFS(Table1[Column1],Table1[Date],'OEE AHV'!$B103,Table1[M/C],'OEE AHV'!$D103,Table1[Case downtime],'OEE AHV'!AO$2) -> 0 | AP103: =SUMIFS(Table1[Column1],Table1[Date],'OEE AHV'!$B103,Table1[M/C],'OEE AHV'!$D103,Table1[Case downtime],'OEE AHV'!AP$2) -> 0 | AQ103: =SUMIFS(Table1[Column1],Table1[Date],'OEE AHV'!$B103,Table1[M/C],'OEE AHV'!$D103,Table1[Case downtime],'OEE AHV'!AQ$2) -> 0 | AR103: =SUMIFS(Table1[Column1],Table1[Date],'OEE AHV'!$B103,Table1[M/C],'OEE AHV'!$D103,Table1[Case downtime],'OEE AHV'!AR$2) -> 0 | AS103: =SUMIFS(Table1[Column1],Table1[Date],'OEE AHV'!$B103,Table1[M/C],'OEE AHV'!$D103,Table1[Case downtime],'OEE AHV'!AS$2) -> 0 | ... AX103: =SUMIFS(Table1[Column1],Table1[Date],'OEE AHV'!$B103,Table1[M/C],'OEE AHV'!$D103,Table1[Case downtime],'OEE AHV'!AX$2) -> 0
B104: 46060 | C104: DRD | D104: AHV-05 | E104: 4.3 | F104: 24 | G104: =F104*60 -> 1440 | H104: 0 | I104: =+G104-H104 -> 1440 | J104: =SUM(AF104:AK104) -> 111.27409 | K104: =SUM(AL104:AX104) -> 48 | L104: =+K104+J104 -> 159.27409 | M104: =+I104-L104 -> 1280.7259 | N104: 9720 | P104: 9211 | Q104: =SUM(N104:P104) -> 18931 | R104: =SUM(Z104:AD104) -> 3 | S104: =+Q104-R104 -> 18928 | T104: =IFERROR((M104*60)/E104,"-") -> 17870.594 | U104: =IFERROR(M104/I104," ") -> 0.88939299 | V104: =IFERROR(Q104/T104," ") -> 1.059338 | W104: =IFERROR(S104/Q104," ") -> 0.99984153 | X104: =IFERROR(U104*V104*W104," ") -> 0.94201852 | Z104: 3 | AE104: =$AE$98 -> 37.960938 | AF104: =(Q104/512*68/60) -> 41.904557 | AG104: =(Q104/512*35/60) -> 21.568522 | AH104: =(Q104/512*37/60) -> 22.801009 | AI104: 10 | AJ104: 5 | AK104: 10 | AL104: =SUMIFS(Table1[Column1],Table1[Date],'OEE AHV'!$B104,Table1[M/C],'OEE AHV'!$D104,Table1[Case downtime],'OEE AHV'!AL$2) -> 0 | AM104: =SUMIFS(Table1[Column1],Table1[Date],'OEE AHV'!$B104,Table1[M/C],'OEE AHV'!$D104,Table1[Case downtime],'OEE AHV'!AM$2) -> 48 | AN104: =SUMIFS(Table1[Column1],Table1[Date],'OEE AHV'!$B104,Table1[M/C],'OEE AHV'!$D104,Table1[Case downtime],'OEE AHV'!AN$2) -> 0 | AO104: =SUMIFS(Table1[Column1],Table1[Date],'OEE AHV'!$B104,Table1[M/C],'OEE AHV'!$D104,Table1[Case downtime],'OEE AHV'!AO$2) -> 0 | AP104: =SUMIFS(Table1[Column1],Table1[Date],'OEE AHV'!$B104,Table1[M/C],'OEE AHV'!$D104,Table1[Case downtime],'OEE AHV'!AP$2) -> 0 | AQ104: =SUMIFS(Table1[Column1],Table1[Date],'OEE AHV'!$B104,Table1[M/C],'OEE AHV'!$D104,Table1[Case downtime],'OEE AHV'!AQ$2) -> 0 | AR104: =SUMIFS(Table1[Column1],Table1[Date],'OEE AHV'!$B104,Table1[M/C],'OEE AHV'!$D104,Table1[Case downtime],'OEE AHV'!AR$2) -> 0 | AS104: =SUMIFS(Table1[Column1],Table1[Date],'OEE AHV'!$B104,Table1[M/C],'OEE AHV'!$D104,Table1[Case downtime],'OEE AHV'!AS$2) -> 0 | ... AX104: =SUMIFS(Table1[Column1],Table1[Date],'OEE AHV'!$B104,Table1[M/C],'OEE AHV'!$D104,Table1[Case downtime],'OEE AHV'!AX$2) -> 0
B105: 46061 | C105: DRD | D105: AHV-05 | E105: 4.3 | F105: 12 | G105: =F105*60 -> 720 | H105: 0 | I105: =+G105-H105 -> 720 | J105: =SUM(AF105:AK105) -> 57.657552 | K105: =SUM(AL105:AX105) -> 0 | L105: =+K105+J105 -> 57.657552 | M105: =+I105-L105 -> 662.34245 | N105: 0 | P105: 7166 | Q105: =SUM(N105:P105) -> 7166 | R105: =SUM(Z105:AD105) -> 0 | S105: =+Q105-R105 -> 7166 | T105: =IFERROR((M105*60)/E105,"-") -> 9241.9876 | U105: =IFERROR(M105/I105," ") -> 0.91992007 | V105: =IFERROR(Q105/T105," ") -> 0.77537433 | W105: =IFERROR(S105/Q105," ") -> 1 | X105: =IFERROR(U105*V105*W105," ") -> 0.71328241 | Z105: 0 | AE105: =$AE$98 -> 37.960938 | AF105: =(Q105/512*68/60) -> 15.86224 | AG105: =(Q105/512*35/60) -> 8.164388 | AH105: =(Q105/512*37/60) -> 8.6309245 | AI105: 10 | AJ105: 5 | AK105: 10 | AL105: =SUMIFS(Table1[Column1],Table1[Date],'OEE AHV'!$B105,Table1[M/C],'OEE AHV'!$D105,Table1[Case downtime],'OEE AHV'!AL$2) -> 0 | AM105: =SUMIFS(Table1[Column1],Table1[Date],'OEE AHV'!$B105,Table1[M/C],'OEE AHV'!$D105,Table1[Case downtime],'OEE AHV'!AM$2) -> 0 | AN105: =SUMIFS(Table1[Column1],Table1[Date],'OEE AHV'!$B105,Table1[M/C],'OEE AHV'!$D105,Table1[Case downtime],'OEE AHV'!AN$2) -> 0 | AO105: =SUMIFS(Table1[Column1],Table1[Date],'OEE AHV'!$B105,Table1[M/C],'OEE AHV'!$D105,Table1[Case downtime],'OEE AHV'!AO$2) -> 0 | AP105: =SUMIFS(Table1[Column1],Table1[Date],'OEE AHV'!$B105,Table1[M/C],'OEE AHV'!$D105,Table1[Case downtime],'OEE AHV'!AP$2) -> 0 | AQ105: =SUMIFS(Table1[Column1],Table1[Date],'OEE AHV'!$B105,Table1[M/C],'OEE AHV'!$D105,Table1[Case downtime],'OEE AHV'!AQ$2) -> 0 | AR105: =SUMIFS(Table1[Column1],Table1[Date],'OEE AHV'!$B105,Table1[M/C],'OEE AHV'!$D105,Table1[Case downtime],'OEE AHV'!AR$2) -> 0 | AS105: =SUMIFS(Table1[Column1],Table1[Date],'OEE AHV'!$B105,Table1[M/C],'OEE AHV'!$D105,Table1[Case downtime],'OEE AHV'!AS$2) -> 0 | ... AX105: =SUMIFS(Table1[Column1],Table1[Date],'OEE AHV'!$B105,Table1[M/C],'OEE AHV'!$D105,Table1[Case downtime],'OEE AHV'!AX$2) -> 0
B106: 46062 | C106: DRD | D106: AHV-05 | E106: 4.3 | F106: 24 | G106: =F106*60 -> 1440 | H106: 0 | I106: =+G106-H106 -> 1440 | J106: =SUM(AF106:AK106) -> 99.616536 | K106: =SUM(AL106:AX106) -> 139 | L106: =+K106+J106 -> 238.61654 | M106: =+I106-L106 -> 1201.3835 | N106: 7164 | P106: 9209 | Q106: =SUM(N106:P106) -> 16373 | R106: =SUM(Z106:AD106) -> 8 | S106: =+Q106-R106 -> 16365 | T106: =IFERROR((M106*60)/E106,"-") -> 16763.49 | U106: =IFERROR(M106/I106," ") -> 0.83429407 | V106: =IFERROR(Q106/T106," ") -> 0.97670591 | W106: =IFERROR(S106/Q106," ") -> 0.99951139 | X106: =IFERROR(U106*V106*W106," ") -> 0.81446181 | Z106: 8 | AE106: =$AE$98 -> 37.960938 | AF106: =(Q106/512*68/60) -> 36.242318 | AG106: =(Q106/512*35/60) -> 18.654134 | AH106: =(Q106/512*37/60) -> 19.720085 | AI106: 10 | AJ106: 5 | AK106: 10 | AL106: =SUMIFS(Table1[Column1],Table1[Date],'OEE AHV'!$B106,Table1[M/C],'OEE AHV'!$D106,Table1[Case downtime],'OEE AHV'!AL$2) -> 44 | AM106: =SUMIFS(Table1[Column1],Table1[Date],'OEE AHV'!$B106,Table1[M/C],'OEE AHV'!$D106,Table1[Case downtime],'OEE AHV'!AM$2) -> 0 | AN106: =SUMIFS(Table1[Column1],Table1[Date],'OEE AHV'!$B106,Table1[M/C],'OEE AHV'!$D106,Table1[Case downtime],'OEE AHV'!AN$2) -> 0 | AO106: =SUMIFS(Table1[Column1],Table1[Date],'OEE AHV'!$B106,Table1[M/C],'OEE AHV'!$D106,Table1[Case downtime],'OEE AHV'!AO$2) -> 0 | AP106: =SUMIFS(Table1[Column1],Table1[Date],'OEE AHV'!$B106,Table1[M/C],'OEE AHV'!$D106,Table1[Case downtime],'OEE AHV'!AP$2) -> 0 | AQ106: =SUMIFS(Table1[Column1],Table1[Date],'OEE AHV'!$B106,Table1[M/C],'OEE AHV'!$D106,Table1[Case downtime],'OEE AHV'!AQ$2) -> 0 | AR106: =SUMIFS(Table1[Column1],Table1[Date],'OEE AHV'!$B106,Table1[M/C],'OEE AHV'!$D106,Table1[Case downtime],'OEE AHV'!AR$2) -> 0 | AS106: =SUMIFS(Table1[Column1],Table1[Date],'OEE AHV'!$B106,Table1[M/C],'OEE AHV'!$D106,Table1[Case downtime],'OEE AHV'!AS$2) -> 0 | ... AX106: =SUMIFS(Table1[Column1],Table1[Date],'OEE AHV'!$B106,Table1[M/C],'OEE AHV'!$D106,Table1[Case downtime],'OEE AHV'!AX$2) -> 0
B107: 46063 | C107: DRD | D107: AHV-05 | E107: 4.3 | F107: 24 | G107: =F107*60 -> 1440 | H107: 0 | I107: =+G107-H107 -> 1440 | J107: =SUM(AF107:AK107) -> 108.94531 | K107: =SUM(AL107:AX107) -> 0 | L107: =+K107+J107 -> 108.94531 | M107: =+I107-L107 -> 1331.0547 | N107: 9720 | P107: 8700 | Q107: =SUM(N107:P107) -> 18420 | R107: =SUM(Z107:AD107) -> 0 | S107: =+Q107-R107 -> 18420 | T107: =IFERROR((M107*60)/E107,"-") -> 18572.856 | U107: =IFERROR(M107/I107," ") -> 0.92434353 | V107: =IFERROR(Q107/T107," ") -> 0.99176992 | W107: =IFERROR(S107/Q107," ") -> 1 | X107: =IFERROR(U107*V107*W107," ") -> 0.91673611 | Z107: 0 | AE107: =$AE$98 -> 37.960938 | AF107: =(Q107/512*68/60) -> 40.773438 | AG107: =(Q107/512*35/60) -> 20.986328 | AH107: =(Q107/512*37/60) -> 22.185547 | AI107: 10 | AJ107: 5 | AK107: 10 | AL107: =SUMIFS(Table1[Column1],Table1[Date],'OEE AHV'!#REF!,Table1[M/C],'OEE AHV'!#REF!,Table1[Case downtime],'OEE AHV'!AL$2) -> 0 | AM107: =SUMIFS(Table1[Column1],Table1[Date],'OEE AHV'!#REF!,Table1[M/C],'OEE AHV'!#REF!,Table1[Case downtime],'OEE AHV'!AM$2) -> 0 | AN107: =SUMIFS(Table1[Column1],Table1[Date],'OEE AHV'!#REF!,Table1[M/C],'OEE AHV'!#REF!,Table1[Case downtime],'OEE AHV'!AN$2) -> 0 | AO107: =SUMIFS(Table1[Column1],Table1[Date],'OEE AHV'!#REF!,Table1[M/C],'OEE AHV'!#REF!,Table1[Case downtime],'OEE AHV'!AO$2) -> 0 | AP107: =SUMIFS(Table1[Column1],Table1[Date],'OEE AHV'!#REF!,Table1[M/C],'OEE AHV'!#REF!,Table1[Case downtime],'OEE AHV'!AP$2) -> 0 | AQ107: =SUMIFS(Table1[Column1],Table1[Date],'OEE AHV'!#REF!,Table1[M/C],'OEE AHV'!#REF!,Table1[Case downtime],'OEE AHV'!AQ$2) -> 0 | AR107: =SUMIFS(Table1[Column1],Table1[Date],'OEE AHV'!#REF!,Table1[M/C],'OEE AHV'!#REF!,Table1[Case downtime],'OEE AHV'!AR$2) -> 0 | AS107: =SUMIFS(Table1[Column1],Table1[Date],'OEE AHV'!#REF!,Table1[M/C],'OEE AHV'!#REF!,Table1[Case downtime],'OEE AHV'!AS$2) -> 0 | ... AX107: =SUMIFS(Table1[Column1],Table1[Date],'OEE AHV'!#REF!,Table1[M/C],'OEE AHV'!#REF!,Table1[Case downtime],'OEE AHV'!AX$2) -> 0
B108: 46064 | C108: DRD | D108: AHV-05 | E108: 4.3 | F108: 24 | G108: =F108*60 -> 1440 | H108: 0 | I108: =+G108-H108 -> 1440 | J108: =SUM(AF108:AK108) -> 106.64388 | K108: =SUM(AL108:AX108) -> 0 | L108: =+K108+J108 -> 106.64388 | M108: =+I108-L108 -> 1333.3561 | N108: 9728 | P108: 8187 | Q108: =SUM(N108:P108) -> 17915 | R108: =SUM(Z108:AD108) -> 2 | S108: =+Q108-R108 -> 17913 | T108: =IFERROR((M108*60)/E108,"-") -> 18604.969 | U108: =IFERROR(M108/I108," ") -> 0.92594175 | V108: =IFERROR(Q108/T108," ") -> 0.96291479 | W108: =IFERROR(S108/Q108," ") -> 0.99988836 | X108: =IFERROR(U108*V108*W108," ") -> 0.89150347 | Z108: 2 | AE108: =$AE$98 -> 37.960938 | AF108: =(Q108/512*68/60) -> 39.655599 | AG108: =(Q108/512*35/60) -> 20.41097 | AH108: =(Q108/512*37/60) -> 21.577311 | AI108: 10 | AJ108: 5 | AK108: 10 | AL108: =SUMIFS(Table1[Column1],Table1[Date],'OEE AHV'!#REF!,Table1[M/C],'OEE AHV'!#REF!,Table1[Case downtime],'OEE AHV'!AL$2) -> 0 | AM108: =SUMIFS(Table1[Column1],Table1[Date],'OEE AHV'!#REF!,Table1[M/C],'OEE AHV'!#REF!,Table1[Case downtime],'OEE AHV'!AM$2) -> 0 | AN108: =SUMIFS(Table1[Column1],Table1[Date],'OEE AHV'!#REF!,Table1[M/C],'OEE AHV'!#REF!,Table1[Case downtime],'OEE AHV'!AN$2) -> 0 | AO108: =SUMIFS(Table1[Column1],Table1[Date],'OEE AHV'!#REF!,Table1[M/C],'OEE AHV'!#REF!,Table1[Case downtime],'OEE AHV'!AO$2) -> 0 | AP108: =SUMIFS(Table1[Column1],Table1[Date],'OEE AHV'!#REF!,Table1[M/C],'OEE AHV'!#REF!,Table1[Case downtime],'OEE AHV'!AP$2) -> 0 | AQ108: =SUMIFS(Table1[Column1],Table1[Date],'OEE AHV'!#REF!,Table1[M/C],'OEE AHV'!#REF!,Table1[Case downtime],'OEE AHV'!AQ$2) -> 0 | AR108: =SUMIFS(Table1[Column1],Table1[Date],'OEE AHV'!#REF!,Table1[M/C],'OEE AHV'!#REF!,Table1[Case downtime],'OEE AHV'!AR$2) -> 0 | AS108: =SUMIFS(Table1[Column1],Table1[Date],'OEE AHV'!#REF!,Table1[M/C],'OEE AHV'!#REF!,Table1[Case downtime],'OEE AHV'!AS$2) -> 0 | ... AX108: =SUMIFS(Table1[Column1],Table1[Date],'OEE AHV'!#REF!,Table1[M/C],'OEE AHV'!#REF!,Table1[Case downtime],'OEE AHV'!AX$2) -> 0
B109: 46065 | C109: DRD | D109: AHV-05 | E109: 4.3 | F109: 24 | G109: =F109*60 -> 1440 | H109: 0 | I109: =+G109-H109 -> 1440 | J109: =SUM(AF109:AK109) -> 97.260417 | K109: =SUM(AL109:AX109) -> 0 | L109: =+K109+J109 -> 97.260417 | M109: =+I109-L109 -> 1342.7396 | N109: 8695 | P109: 7161 | Q109: =SUM(N109:P109) -> 15856 | R109: =SUM(Z109:AD109) -> 13 | S109: =+Q109-R109 -> 15843 | T109: =IFERROR((M109*60)/E109,"-") -> 18735.901 | U109: =IFERROR(M109/I109," ") -> 0.93245804 | V109: =IFERROR(Q109/T109," ") -> 0.84628969 | W109: =IFERROR(S109/Q109," ") -> 0.99918012 | X109: =IFERROR(U109*V109*W109," ") -> 0.78848264 | Z109: 13 | AE109: =$AE$98 -> 37.960938 | AF109: =(Q109/512*68/60) -> 35.097917 | AG109: =(Q109/512*35/60) -> 18.065104 | AH109: =(Q109/512*37/60) -> 19.097396 | AI109: 10 | AJ109: 5 | AK109: 10 | AL109: =SUMIFS(Table1[Column1],Table1[Date],'OEE AHV'!#REF!,Table1[M/C],'OEE AHV'!#REF!,Table1[Case downtime],'OEE AHV'!AL$2) -> 0 | AM109: =SUMIFS(Table1[Column1],Table1[Date],'OEE AHV'!#REF!,Table1[M/C],'OEE AHV'!#REF!,Table1[Case downtime],'OEE AHV'!AM$2) -> 0 | AN109: =SUMIFS(Table1[Column1],Table1[Date],'OEE AHV'!#REF!,Table1[M/C],'OEE AHV'!#REF!,Table1[Case downtime],'OEE AHV'!AN$2) -> 0 | AO109: =SUMIFS(Table1[Column1],Table1[Date],'OEE AHV'!#REF!,Table1[M/C],'OEE AHV'!#REF!,Table1[Case downtime],'OEE AHV'!AO$2) -> 0 | AP109: =SUMIFS(Table1[Column1],Table1[Date],'OEE AHV'!#REF!,Table1[M/C],'OEE AHV'!#REF!,Table1[Case downtime],'OEE AHV'!AP$2) -> 0 | AQ109: =SUMIFS(Table1[Column1],Table1[Date],'OEE AHV'!#REF!,Table1[M/C],'OEE AHV'!#REF!,Table1[Case downtime],'OEE AHV'!AQ$2) -> 0 | AR109: =SUMIFS(Table1[Column1],Table1[Date],'OEE AHV'!#REF!,Table1[M/C],'OEE AHV'!#REF!,Table1[Case downtime],'OEE AHV'!AR$2) -> 0 | AS109: =SUMIFS(Table1[Column1],Table1[Date],'OEE AHV'!#REF!,Table1[M/C],'OEE AHV'!#REF!,Table1[Case downtime],'OEE AHV'!AS$2) -> 0 | ... AX109: =SUMIFS(Table1[Column1],Table1[Date],'OEE AHV'!#REF!,Table1[M/C],'OEE AHV'!#REF!,Table1[Case downtime],'OEE AHV'!AX$2) -> 0
B110: 46066 | C110: DRD | D110: AHV-05 | E110: 4.3 | F110: 24 | G110: =F110*60 -> 1440 | H110: 0 | I110: =+G110-H110 -> 1440 | J110: =SUM(AF110:AK110) -> 113.59831 | K110: =SUM(AL110:AX110) -> 0 | L110: =+K110+J110 -> 113.59831 | M110: =+I110-L110 -> 1326.4017 | N110: 9721 | P110: 9720 | Q110: =SUM(N110:P110) -> 19441 | R110: =SUM(Z110:AD110) -> 7 | S110: =+Q110-R110 -> 19434 | T110: =IFERROR((M110*60)/E110,"-") -> 18507.931 | U110: =IFERROR(M110/I110," ") -> 0.92111229 | V110: =IFERROR(Q110/T110," ") -> 1.0504146 | W110: =IFERROR(S110/Q110," ") -> 0.99963994 | X110: =IFERROR(U110*V110*W110," ") -> 0.96720139 | Z110: 7 | AE110: =$AE$98 -> 37.960938 | AF110: =(Q110/512*68/60) -> 43.033464 | AG110: =(Q110/512*35/60) -> 22.149577 | AH110: =(Q110/512*37/60) -> 23.415267 | AI110: 10 | AJ110: 5 | AK110: 10 | AL110: =SUMIFS(Table1[Column1],Table1[Date],'OEE AHV'!#REF!,Table1[M/C],'OEE AHV'!#REF!,Table1[Case downtime],'OEE AHV'!AL$2) -> 0 | AM110: =SUMIFS(Table1[Column1],Table1[Date],'OEE AHV'!#REF!,Table1[M/C],'OEE AHV'!#REF!,Table1[Case downtime],'OEE AHV'!AM$2) -> 0 | AN110: =SUMIFS(Table1[Column1],Table1[Date],'OEE AHV'!#REF!,Table1[M/C],'OEE AHV'!#REF!,Table1[Case downtime],'OEE AHV'!AN$2) -> 0 | AO110: =SUMIFS(Table1[Column1],Table1[Date],'OEE AHV'!#REF!,Table1[M/C],'OEE AHV'!#REF!,Table1[Case downtime],'OEE AHV'!AO$2) -> 0 | AP110: =SUMIFS(Table1[Column1],Table1[Date],'OEE AHV'!#REF!,Table1[M/C],'OEE AHV'!#REF!,Table1[Case downtime],'OEE AHV'!AP$2) -> 0 | AQ110: =SUMIFS(Table1[Column1],Table1[Date],'OEE AHV'!#REF!,Table1[M/C],'OEE AHV'!#REF!,Table1[Case downtime],'OEE AHV'!AQ$2) -> 0 | AR110: =SUMIFS(Table1[Column1],Table1[Date],'OEE AHV'!#REF!,Table1[M/C],'OEE AHV'!#REF!,Table1[Case downtime],'OEE AHV'!AR$2) -> 0 | AS110: =SUMIFS(Table1[Column1],Table1[Date],'OEE AHV'!#REF!,Table1[M/C],'OEE AHV'!#REF!,Table1[Case downtime],'OEE AHV'!AS$2) -> 0 | ... AX110: =SUMIFS(Table1[Column1],Table1[Date],'OEE AHV'!#REF!,Table1[M/C],'OEE AHV'!#REF!,Table1[Case downtime],'OEE AHV'!AX$2) -> 0
B111: 46067 | C111: DRD | D111: AHV-05 | E111: 4.3 | F111: 24 | G111: =F111*60 -> 1440 | H111: 0 | I111: =+G111-H111 -> 1440 | J111: =SUM(AF111:AK111) -> 111.22396 | K111: =SUM(AL111:AX111) -> 0 | L111: =+K111+J111 -> 111.22396 | M111: =+I111-L111 -> 1328.776 | N111: 9208 | P111: 9712 | Q111: =SUM(N111:P111) -> 18920 | R111: =SUM(Z111:AD111) -> 8 | S111: =+Q111-R111 -> 18912 | T111: =IFERROR((M111*60)/E111,"-") -> 18541.061 | U111: =IFERROR(M111/I111," ") -> 0.92276114 | V111: =IFERROR(Q111/T111," ") -> 1.0204378 | W111: =IFERROR(S111/Q111," ") -> 0.99957717 | X111: =IFERROR(U111*V111*W111," ") -> 0.94122222 | Z111: 8 | AE111: =$AE$98 -> 37.960938 | AF111: =(Q111/512*68/60) -> 41.880208 | AG111: =(Q111/512*35/60) -> 21.55599 | AH111: =(Q111/512*37/60) -> 22.78776 | AI111: 10 | AJ111: 5 | AK111: 10 | AL111: =SUMIFS(Table1[Column1],Table1[Date],'OEE AHV'!#REF!,Table1[M/C],'OEE AHV'!#REF!,Table1[Case downtime],'OEE AHV'!AL$2) -> 0 | AM111: =SUMIFS(Table1[Column1],Table1[Date],'OEE AHV'!#REF!,Table1[M/C],'OEE AHV'!#REF!,Table1[Case downtime],'OEE AHV'!AM$2) -> 0 | AN111: =SUMIFS(Table1[Column1],Table1[Date],'OEE AHV'!#REF!,Table1[M/C],'OEE AHV'!#REF!,Table1[Case downtime],'OEE AHV'!AN$2) -> 0 | AO111: =SUMIFS(Table1[Column1],Table1[Date],'OEE AHV'!#REF!,Table1[M/C],'OEE AHV'!#REF!,Table1[Case downtime],'OEE AHV'!AO$2) -> 0 | AP111: =SUMIFS(Table1[Column1],Table1[Date],'OEE AHV'!#REF!,Table1[M/C],'OEE AHV'!#REF!,Table1[Case downtime],'OEE AHV'!AP$2) -> 0 | AQ111: =SUMIFS(Table1[Column1],Table1[Date],'OEE AHV'!#REF!,Table1[M/C],'OEE AHV'!#REF!,Table1[Case downtime],'OEE AHV'!AQ$2) -> 0 | AR111: =SUMIFS(Table1[Column1],Table1[Date],'OEE AHV'!#REF!,Table1[M/C],'OEE AHV'!#REF!,Table1[Case downtime],'OEE AHV'!AR$2) -> 0 | AS111: =SUMIFS(Table1[Column1],Table1[Date],'OEE AHV'!#REF!,Table1[M/C],'OEE AHV'!#REF!,Table1[Case downtime],'OEE AHV'!AS$2) -> 0 | ... AX111: =SUMIFS(Table1[Column1],Table1[Date],'OEE AHV'!#REF!,Table1[M/C],'OEE AHV'!#REF!,Table1[Case downtime],'OEE AHV'!AX$2) -> 0
B112: 46069 | C112: DRD | D112: AHV-05 | E112: 4.3 | F112: 24 | G112: =F112*60 -> 1440 | H112: 0 | I112: =+G112-H112 -> 1440 | J112: =SUM(AF112:AK112) -> 108.96354 | K112: =SUM(AL112:AX112) -> 0 | L112: =+K112+J112 -> 108.96354 | M112: =+I112-L112 -> 1331.0365 | N112: 9208 | P112: 9216 | Q112: =SUM(N112:P112) -> 18424 | R112: =SUM(Z112:AD112) -> 3 | S112: =+Q112-R112 -> 18421 | T112: =IFERROR((M112*60)/E112,"-") -> 18572.602 | U112: =IFERROR(M112/I112," ") -> 0.92433087 | V112: =IFERROR(Q112/T112," ") -> 0.99199887 | W112: =IFERROR(S112/Q112," ") -> 0.99983717 | X112: =IFERROR(U112*V112*W112," ") -> 0.91678588 | Z112: 3 | AE112: =$AE$98 -> 37.960938 | AF112: =(Q112/512*68/60) -> 40.782292 | AG112: =(Q112/512*35/60) -> 20.990885 | AH112: =(Q112/512*37/60) -> 22.190365 | AI112: 10 | AJ112: 5 | AK112: 10 | AL112: =SUMIFS(Table1[Column1],Table1[Date],'OEE AHV'!#REF!,Table1[M/C],'OEE AHV'!#REF!,Table1[Case downtime],'OEE AHV'!AL$2) -> 0 | AM112: =SUMIFS(Table1[Column1],Table1[Date],'OEE AHV'!#REF!,Table1[M/C],'OEE AHV'!#REF!,Table1[Case downtime],'OEE AHV'!AM$2) -> 0 | AN112: =SUMIFS(Table1[Column1],Table1[Date],'OEE AHV'!#REF!,Table1[M/C],'OEE AHV'!#REF!,Table1[Case downtime],'OEE AHV'!AN$2) -> 0 | AO112: =SUMIFS(Table1[Column1],Table1[Date],'OEE AHV'!#REF!,Table1[M/C],'OEE AHV'!#REF!,Table1[Case downtime],'OEE AHV'!AO$2) -> 0 | AP112: =SUMIFS(Table1[Column1],Table1[Date],'OEE AHV'!#REF!,Table1[M/C],'OEE AHV'!#REF!,Table1[Case downtime],'OEE AHV'!AP$2) -> 0 | AQ112: =SUMIFS(Table1[Column1],Table1[Date],'OEE AHV'!#REF!,Table1[M/C],'OEE AHV'!#REF!,Table1[Case downtime],'OEE AHV'!AQ$2) -> 0 | AR112: =SUMIFS(Table1[Column1],Table1[Date],'OEE AHV'!#REF!,Table1[M/C],'OEE AHV'!#REF!,Table1[Case downtime],'OEE AHV'!AR$2) -> 0 | AS112: =SUMIFS(Table1[Column1],Table1[Date],'OEE AHV'!#REF!,Table1[M/C],'OEE AHV'!#REF!,Table1[Case downtime],'OEE AHV'!AS$2) -> 0 | ... AX112: =SUMIFS(Table1[Column1],Table1[Date],'OEE AHV'!#REF!,Table1[M/C],'OEE AHV'!#REF!,Table1[Case downtime],'OEE AHV'!AX$2) -> 0
B113: 46070 | C113: DRD | D113: AHV-05 | E113: 4.3 | F113: 24 | G113: =F113*60 -> 1440 | H113: 0 | I113: =+G113-H113 -> 1440 | J113: =SUM(AF113:AK113) -> 111.2194 | K113: =SUM(AL113:AX113) -> 0 | L113: =+K113+J113 -> 111.2194 | M113: =+I113-L113 -> 1328.7806 | N113: 9208 | P113: 9711 | Q113: =SUM(N113:P113) -> 18919 | R113: =SUM(Z113:AD113) -> 6 | S113: =+Q113-R113 -> 18913 | T113: =IFERROR((M113*60)/E113,"-") -> 18541.125 | U113: =IFERROR(M113/I113," ") -> 0.9227643 | V113: =IFERROR(Q113/T113," ") -> 1.0203804 | W113: =IFERROR(S113/Q113," ") -> 0.99968286 | X113: =IFERROR(U113*V113*W113," ") -> 0.94127199 | Z113: 6 | AE113: =$AE$98 -> 37.960938 | AF113: =(Q113/512*68/60) -> 41.877995 | AG113: =(Q113/512*35/60) -> 21.55485 | AH113: =(Q113/512*37/60) -> 22.786556 | AI113: 10 | AJ113: 5 | AK113: 10 | AL113: =SUMIFS(Table1[Column1],Table1[Date],'OEE AHV'!#REF!,Table1[M/C],'OEE AHV'!#REF!,Table1[Case downtime],'OEE AHV'!AL$2) -> 0 | AM113: =SUMIFS(Table1[Column1],Table1[Date],'OEE AHV'!#REF!,Table1[M/C],'OEE AHV'!#REF!,Table1[Case downtime],'OEE AHV'!AM$2) -> 0 | AN113: =SUMIFS(Table1[Column1],Table1[Date],'OEE AHV'!#REF!,Table1[M/C],'OEE AHV'!#REF!,Table1[Case downtime],'OEE AHV'!AN$2) -> 0 | AO113: =SUMIFS(Table1[Column1],Table1[Date],'OEE AHV'!#REF!,Table1[M/C],'OEE AHV'!#REF!,Table1[Case downtime],'OEE AHV'!AO$2) -> 0 | AP113: =SUMIFS(Table1[Column1],Table1[Date],'OEE AHV'!#REF!,Table1[M/C],'OEE AHV'!#REF!,Table1[Case downtime],'OEE AHV'!AP$2) -> 0 | AQ113: =SUMIFS(Table1[Column1],Table1[Date],'OEE AHV'!#REF!,Table1[M/C],'OEE AHV'!#REF!,Table1[Case downtime],'OEE AHV'!AQ$2) -> 0 | AR113: =SUMIFS(Table1[Column1],Table1[Date],'OEE AHV'!#REF!,Table1[M/C],'OEE AHV'!#REF!,Table1[Case downtime],'OEE AHV'!AR$2) -> 0 | AS113: =SUMIFS(Table1[Column1],Table1[Date],'OEE AHV'!#REF!,Table1[M/C],'OEE AHV'!#REF!,Table1[Case downtime],'OEE AHV'!AS$2) -> 0 | ... AX113: =SUMIFS(Table1[Column1],Table1[Date],'OEE AHV'!#REF!,Table1[M/C],'OEE AHV'!#REF!,Table1[Case downtime],'OEE AHV'!AX$2) -> 0
B114: 46071 | C114: DRD | D114: AHV-05 | E114: 4.3 | F114: 24 | G114: =F114*60 -> 1440 | H114: 0 | I114: =+G114-H114 -> 1440 | J114: =SUM(AF114:AK114) -> 113.63021 | K114: =SUM(AL114:AX114) -> 0 | L114: =+K114+J114 -> 113.63021 | M114: =+I114-L114 -> 1326.3698 | N114: 9724 | P114: 9724 | Q114: =SUM(N114:P114) -> 19448 | R114: =SUM(Z114:AD114) -> 0 | S114: =+Q114-R114 -> 19448 | T114: =IFERROR((M114*60)/E114,"-") -> 18507.485 | U114: =IFERROR(M114/I114," ") -> 0.92109013 | V114: =IFERROR(Q114/T114," ") -> 1.0508181 | W114: =IFERROR(S114/Q114," ") -> 1 | X114: =IFERROR(U114*V114*W114," ") -> 0.96789815 | Z114: 0 | AE114: =$AE$98 -> 37.960938 | AF114: =(Q114/512*68/60) -> 43.048958 | AG114: =(Q114/512*35/60) -> 22.157552 | AH114: =(Q114/512*37/60) -> 23.423698 | AI114: 10 | AJ114: 5 | AK114: 10 | AL114: =SUMIFS(Table1[Column1],Table1[Date],'OEE AHV'!#REF!,Table1[M/C],'OEE AHV'!#REF!,Table1[Case downtime],'OEE AHV'!AL$2) -> 0 | AM114: =SUMIFS(Table1[Column1],Table1[Date],'OEE AHV'!#REF!,Table1[M/C],'OEE AHV'!#REF!,Table1[Case downtime],'OEE AHV'!AM$2) -> 0 | AN114: =SUMIFS(Table1[Column1],Table1[Date],'OEE AHV'!#REF!,Table1[M/C],'OEE AHV'!#REF!,Table1[Case downtime],'OEE AHV'!AN$2) -> 0 | AO114: =SUMIFS(Table1[Column1],Table1[Date],'OEE AHV'!#REF!,Table1[M/C],'OEE AHV'!#REF!,Table1[Case downtime],'OEE AHV'!AO$2) -> 0 | AP114: =SUMIFS(Table1[Column1],Table1[Date],'OEE AHV'!#REF!,Table1[M/C],'OEE AHV'!#REF!,Table1[Case downtime],'OEE AHV'!AP$2) -> 0 | AQ114: =SUMIFS(Table1[Column1],Table1[Date],'OEE AHV'!#REF!,Table1[M/C],'OEE AHV'!#REF!,Table1[Case downtime],'OEE AHV'!AQ$2) -> 0 | AR114: =SUMIFS(Table1[Column1],Table1[Date],'OEE AHV'!#REF!,Table1[M/C],'OEE AHV'!#REF!,Table1[Case downtime],'OEE AHV'!AR$2) -> 0 | AS114: =SUMIFS(Table1[Column1],Table1[Date],'OEE AHV'!#REF!,Table1[M/C],'OEE AHV'!#REF!,Table1[Case downtime],'OEE AHV'!AS$2) -> 0 | ... AX114: =SUMIFS(Table1[Column1],Table1[Date],'OEE AHV'!#REF!,Table1[M/C],'OEE AHV'!#REF!,Table1[Case downtime],'OEE AHV'!AX$2) -> 0
